(venv) PS C:\Users\dagcu\AurelisEC\backend> python manage.py runserver -v 2
Watching for file changes with StatReloader
Performing system checks...

System check identified no issues (0 silenced).
Exception in thread django-main-thread:
Traceback (most recent call last):
  File "C:\Users\dagcu\AurelisEC\venv\Lib\site-packages\django\db\backends\base\base.py", line 279, in ensure_connection
    self.connect()
  File "C:\Users\dagcu\AurelisEC\venv\Lib\site-packages\django\utils\asyncio.py", line 26, in inner
    return func(*args, **kwargs)
           ^^^^^^^^^^^^^^^^^^^^^
  File "C:\Users\dagcu\AurelisEC\venv\Lib\site-packages\django\db\backends\base\base.py", line 256, in connect
    self.connection = self.get_new_connection(conn_params)
                      ^^^^^^^^^^^^^^^^^^^^^^^^^^^^^^^^^^^^
  File "C:\Users\dagcu\AurelisEC\venv\Lib\site-packages\django\utils\asyncio.py", line 26, in inner
    return func(*args, **kwargs)
           ^^^^^^^^^^^^^^^^^^^^^
  File "C:\Users\dagcu\AurelisEC\venv\Lib\site-packages\django\db\backends\postgresql\base.py", line 332, in get_new_connection
    connection = self.Database.connect(**conn_params)
                 ^^^^^^^^^^^^^^^^^^^^^^^^^^^^^^^^^^^^
  File "C:\Users\dagcu\AurelisEC\venv\Lib\site-packages\psycopg\connection.py", line 118, in connect
    raise last_ex.with_traceback(None)
psycopg.errors.ConnectionTimeout: connection timeout expired

The above exception was the direct cause of the following exception:

Traceback (most recent call last):
  File "C:\Users\dagcu\AppData\Local\Programs\Python\Python312\Lib\threading.py", line 1073, in _bootstrap_inner
    self.run()
  File "C:\Users\dagcu\AppData\Local\Programs\Python\Python312\Lib\threading.py", line 1010, in run
    self._target(*self._args, **self._kwargs)
  File "C:\Users\dagcu\AurelisEC\venv\Lib\site-packages\django\utils\autoreload.py", line 64, in wrapper
    fn(*args, **kwargs)
  File "C:\Users\dagcu\AurelisEC\venv\Lib\site-packages\django\core\management\commands\runserver.py", line 137, in inner_run
    self.check_migrations()
  File "C:\Users\dagcu\AurelisEC\venv\Lib\site-packages\django\core\management\base.py", line 587, in check_migrations    
    executor = MigrationExecutor(connections[DEFAULT_DB_ALIAS])
               ^^^^^^^^^^^^^^^^^^^^^^^^^^^^^^^^^^^^^^^^^^^^^^^^
  File "C:\Users\dagcu\AurelisEC\venv\Lib\site-packages\django\db\migrations\executor.py", line 18, in __init__
    self.loader = MigrationLoader(self.connection)
                  ^^^^^^^^^^^^^^^^^^^^^^^^^^^^^^^^
  File "C:\Users\dagcu\AurelisEC\venv\Lib\site-packages\django\db\migrations\loader.py", line 58, in __init__
    self.build_graph()
  File "C:\Users\dagcu\AurelisEC\venv\Lib\site-packages\django\db\migrations\loader.py", line 235, in build_graph
    self.applied_migrations = recorder.applied_migrations()
                              ^^^^^^^^^^^^^^^^^^^^^^^^^^^^^
  File "C:\Users\dagcu\AurelisEC\venv\Lib\site-packages\django\db\migrations\recorder.py", line 89, in applied_migrations 
    if self.has_table():
       ^^^^^^^^^^^^^^^^
  File "C:\Users\dagcu\AurelisEC\venv\Lib\site-packages\django\db\migrations\recorder.py", line 63, in has_table
    with self.connection.cursor() as cursor:
         ^^^^^^^^^^^^^^^^^^^^^^^^
  File "C:\Users\dagcu\AurelisEC\venv\Lib\site-packages\django\utils\asyncio.py", line 26, in inner
    return func(*args, **kwargs)
           ^^^^^^^^^^^^^^^^^^^^^
  File "C:\Users\dagcu\AurelisEC\venv\Lib\site-packages\django\db\backends\base\base.py", line 320, in cursor
    return self._cursor()
           ^^^^^^^^^^^^^^
  File "C:\Users\dagcu\AurelisEC\venv\Lib\site-packages\django\db\backends\base\base.py", line 296, in _cursor
    self.ensure_connection()
  File "C:\Users\dagcu\AurelisEC\venv\Lib\site-packages\django\utils\asyncio.py", line 26, in inner
    return func(*args, **kwargs)
           ^^^^^^^^^^^^^^^^^^^^^
  File "C:\Users\dagcu\AurelisEC\venv\Lib\site-packages\django\db\backends\base\base.py", line 278, in ensure_connection  
    with self.wrap_database_errors:
  File "C:\Users\dagcu\AurelisEC\venv\Lib\site-packages\django\db\utils.py", line 91, in __exit__
    raise dj_exc_value.with_traceback(traceback) from exc_value
  File "C:\Users\dagcu\AurelisEC\venv\Lib\site-packages\django\db\backends\base\base.py", line 279, in ensure_connection  
    self.connect()
  File "C:\Users\dagcu\AurelisEC\venv\Lib\site-packages\django\utils\asyncio.py", line 26, in inner
    return func(*args, **kwargs)
           ^^^^^^^^^^^^^^^^^^^^^
  File "C:\Users\dagcu\AurelisEC\venv\Lib\site-packages\django\db\backends\base\base.py", line 256, in connect
    self.connection = self.get_new_connection(conn_params)
                      ^^^^^^^^^^^^^^^^^^^^^^^^^^^^^^^^^^^^
  File "C:\Users\dagcu\AurelisEC\venv\Lib\site-packages\django\utils\asyncio.py", line 26, in inner
    return func(*args, **kwargs)
           ^^^^^^^^^^^^^^^^^^^^^
  File "C:\Users\dagcu\AurelisEC\venv\Lib\site-packages\django\db\backends\postgresql\base.py", line 332, in get_new_connection
    connection = self.Database.connect(**conn_params)
                 ^^^^^^^^^^^^^^^^^^^^^^^^^^^^^^^^^^^^
  File "C:\Users\dagcu\AurelisEC\venv\Lib\site-packages\psycopg\connection.py", line 118, in connect
    raise last_ex.with_traceback(None)
django.db.utils.OperationalError: connection timeout expired